<?xml version="1.0" encoding="utf-8" ?>
<!-- This URDF was automatically created by SolidWorks to URDF Exporter! Originally created by Stephen Brawner (brawner@gmail.com) 
     Commit Version: 1.6.0-4-g7f85cfe  Build Version: 1.6.7995.38578
     For more information, please see http://wiki.ros.org/sw_urdf_exporter -->
<robot name="arm_science_urdf_2025">
    <link name="base_link">
        <inertial>
            <origin xyz="0.000562616295833556 0.307210512508199 0.0483999631155842" rpy="0 0 0" />
            <mass value="32.6756528098081" />
            <inertia ixx="0.488702072220613" ixy="0.000361538607760467" ixz="-8.23179953718944E-06" iyy="0.93908901474509" iyz="-0.00784257465204439" izz="1.3345447860098" />
        </inertial>
        <visual>
            <origin xyz="0 0 0" rpy="0 0 0" />
            <geometry>
                <mesh filename="package://arm_science_urdf_2025/meshes/base_link.STL" />
            </geometry>
            <material name="">
                <color rgba="0.792156862745098 0.819607843137255 0.933333333333333 1" />
            </material>
        </visual>
        <collision>
            <origin xyz="0 0 0" rpy="0 0 0" />
            <geometry>
                <mesh filename="package://arm_science_urdf_2025/meshes/base_link.STL" />
            </geometry>
        </collision>
    </link>
    <link name="link_1">
        <inertial>
            <origin xyz="-5.3723038179501E-17 5.4844240607617E-07 0.0336041265825655" rpy="0 0 0" />
            <mass value="0.137634968166129" />
            <inertia ixx="0.000294001564310722" ixy="4.79311096122027E-19" ixz="2.90990475662283E-19" iyy="0.000446367257769463" iyz="-3.10211596820905E-09" izz="0.000373994827351754" />
        </inertial>
        <visual>
            <origin xyz="0 0 0" rpy="0 0 0" />
            <geometry>
                <mesh filename="package://arm_science_urdf_2025/meshes/link_1.STL" />
            </geometry>
            <material name="">
                <color rgba="0.792156862745098 0.819607843137255 0.933333333333333 1" />
            </material>
        </visual>
        <collision>
            <origin xyz="0 0 0" rpy="0 0 0" />
            <geometry>
                <mesh filename="package://arm_science_urdf_2025/meshes/link_1.STL" />
            </geometry>
        </collision>
    </link>
    <joint name="joint_1" type="continuous">
        <origin xyz="0 0 0.0135" rpy="0 0 0" />
        <parent link="base_link" />
        <child link="link_1" />
        <axis xyz="0 0 1" />
    </joint>
    <link name="link_2">
        <inertial>
            <origin xyz="0.0316224999999999 -0.0966215327084988 0.148851302099507" rpy="0 0 0" />
            <mass value="1.79663833155198" />
            <inertia ixx="0.0349483664750651" ixy="-1.89347896914271E-18" ixz="9.27200125919648E-18" iyy="0.0329129866831077" iyz="0.00437798607290386" izz="0.0032331177263641" />
        </inertial>
        <visual>
            <origin xyz="0 0 0" rpy="0 0 0" />
            <geometry>
                <mesh filename="package://arm_science_urdf_2025/meshes/link_2.STL" />
            </geometry>
            <material name="">
                <color rgba="0.792156862745098 0.819607843137255 0.933333333333333 1" />
            </material>
        </visual>
        <collision>
            <origin xyz="0 0 0" rpy="0 0 0" />
            <geometry>
                <mesh filename="package://arm_science_urdf_2025/meshes/link_2.STL" />
            </geometry>
        </collision>
    </link>
    <joint name="joint_2" type="continuous">
        <origin xyz="-0.028623 -1.25E-05 0.0747" rpy="0 0 0" />
        <parent link="link_1" />
        <child link="link_2" />
        <axis xyz="-1 0 0" />
    </joint>
    <link name="link_3">
        <inertial>
            <origin xyz="0.03162 0.022527417749687 0.0885307406770253" rpy="0 0 0" />
            <mass value="0.622999243464077" />
            <inertia ixx="0.00205164485746339" ixy="-1.14571948760695E-19" ixz="-9.79669603129417E-21" iyy="0.00200228691765053" iyz="-0.000294247168897305" izz="0.00138625401056328" />
        </inertial>
        <visual>
            <origin xyz="0 0 0" rpy="0 0 0" />
            <geometry>
                <mesh filename="package://arm_science_urdf_2025/meshes/link_3.STL" />
            </geometry>
            <material name="">
                <color rgba="0.792156862745098 0.819607843137255 0.933333333333333 1" />
            </material>
        </visual>
        <collision>
            <origin xyz="0 0 0" rpy="0 0 0" />
            <geometry>
                <mesh filename="package://arm_science_urdf_2025/meshes/link_3.STL" />
            </geometry>
        </collision>
    </link>
    <joint name="joint_3" type="continuous">
        <origin xyz="0 -0.11299 0.38408" rpy="0 0 0" />
        <parent link="link_2" />
        <child link="link_3" />
        <axis xyz="-1 0 0" />
    </joint>
    <link name="drill_bit">
        <inertial>
            <origin xyz="-1.04083408558608E-17 0.025 -1.11022302462516E-16" rpy="0 0 0" />
            <mass value="0.00565486677646163" />
            <inertia ixx="1.22899104608433E-06" ixy="4.39758357380945E-22" ixz="3.60814459902687E-25" iyy="1.01787601976309E-07" iyz="-6.97048882404041E-23" izz="1.22899104608433E-06" />
        </inertial>
        <visual>
            <origin xyz="0 0 0" rpy="0 0 0" />
            <geometry>
                <mesh filename="package://arm_science_urdf_2025/meshes/drill_bit.STL" />
            </geometry>
            <material name="">
                <color rgba="0.792156862745098 0.819607843137255 0.933333333333333 1" />
            </material>
        </visual>
        <collision>
            <origin xyz="0 0 0" rpy="0 0 0" />
            <geometry>
                <mesh filename="package://arm_science_urdf_2025/meshes/drill_bit.STL" />
            </geometry>
        </collision>
    </link>
    <joint name="drill_joint" type="continuous">
        <origin xyz="0.03162 0.085 0.115" rpy="0 0 0" />
        <parent link="link_3" />
        <child link="drill_bit" />
        <axis xyz="0 -1 0" />
    </joint>
    <transmission name="trans_joint_1">
        <type>transmission_interface/SimpleTransmission</type>
        <joint name="joint_1">
            <hardwareInterface>hardware_interface/EffortJointInterface</hardwareInterface>
        </joint>
        <actuator name="joint_1_motor">
            <hardwareInterface>hardware_interface/EffortJointInterface</hardwareInterface>
            <mechanicalReduction>1</mechanicalReduction>
        </actuator>
    </transmission>
    <transmission name="trans_joint_2">
        <type>transmission_interface/SimpleTransmission</type>
        <joint name="joint_2">
            <hardwareInterface>hardware_interface/EffortJointInterface</hardwareInterface>
        </joint>
        <actuator name="joint_2_motor">
            <hardwareInterface>hardware_interface/EffortJointInterface</hardwareInterface>
            <mechanicalReduction>1</mechanicalReduction>
        </actuator>
    </transmission>
    <transmission name="trans_joint_3">
        <type>transmission_interface/SimpleTransmission</type>
        <joint name="joint_3">
            <hardwareInterface>hardware_interface/EffortJointInterface</hardwareInterface>
        </joint>
        <actuator name="joint_3_motor">
            <hardwareInterface>hardware_interface/EffortJointInterface</hardwareInterface>
            <mechanicalReduction>1</mechanicalReduction>
        </actuator>
    </transmission>
    <transmission name="trans_drill_joint">
        <type>transmission_interface/SimpleTransmission</type>
        <joint name="drill_joint">
            <hardwareInterface>hardware_interface/EffortJointInterface</hardwareInterface>
        </joint>
        <actuator name="drill_joint_motor">
            <hardwareInterface>hardware_interface/EffortJointInterface</hardwareInterface>
            <mechanicalReduction>1</mechanicalReduction>
        </actuator>
    </transmission>
    <gazebo>
        <plugin name="gazebo_ros_control" filename="libgazebo_ros_control.so">
            <robotNamespace>/</robotNamespace>
        </plugin>
    </gazebo>
</robot>

